home function called
new home function called
WARNING new home function called
WARNING new home function called
WARNING new home function called
ERROR new home function called
WARNING Not Found: /
WARNING "GET / HTTP/1.1" 404 5125
ERROR new home function called
ERROR Internal Server Error: /detail/1/
Traceback (most recent call last):
  File "/media/bisalgt/External/project/virtualenv/lib/python3.8/site-packages/django/db/backends/utils.py", line 84, in _execute
    return self.cursor.execute(sql, params)
  File "/media/bisalgt/External/project/virtualenv/lib/python3.8/site-packages/django/db/backends/sqlite3/base.py", line 423, in execute
    return Database.Cursor.execute(self, query, params)
sqlite3.OperationalError: no such table: blogs

The above exception was the direct cause of the following exception:

Traceback (most recent call last):
  File "/media/bisalgt/External/project/virtualenv/lib/python3.8/site-packages/django/core/handlers/exception.py", line 47, in inner
    response = get_response(request)
  File "/media/bisalgt/External/project/virtualenv/lib/python3.8/site-packages/django/core/handlers/base.py", line 181, in _get_response
    response = wrapped_callback(request, *callback_args, **callback_kwargs)
  File "/media/bisalgt/External/project/blog/views.py", line 87, in detail_blog
    blog = detail_blog_sql(id)
  File "/media/bisalgt/External/project/blog/views.py", line 80, in detail_blog_sql
    cursor.execute(query, place_holders)
  File "/media/bisalgt/External/project/virtualenv/lib/python3.8/site-packages/django/db/backends/utils.py", line 66, in execute
    return self._execute_with_wrappers(sql, params, many=False, executor=self._execute)
  File "/media/bisalgt/External/project/virtualenv/lib/python3.8/site-packages/django/db/backends/utils.py", line 75, in _execute_with_wrappers
    return executor(sql, params, many, context)
  File "/media/bisalgt/External/project/virtualenv/lib/python3.8/site-packages/django/db/backends/utils.py", line 84, in _execute
    return self.cursor.execute(sql, params)
  File "/media/bisalgt/External/project/virtualenv/lib/python3.8/site-packages/django/db/utils.py", line 90, in __exit__
    raise dj_exc_value.with_traceback(traceback) from exc_value
  File "/media/bisalgt/External/project/virtualenv/lib/python3.8/site-packages/django/db/backends/utils.py", line 84, in _execute
    return self.cursor.execute(sql, params)
  File "/media/bisalgt/External/project/virtualenv/lib/python3.8/site-packages/django/db/backends/sqlite3/base.py", line 423, in execute
    return Database.Cursor.execute(self, query, params)
django.db.utils.OperationalError: no such table: blogs
WARNING Not Found: /favicon.ico
WARNING "GET /favicon.ico HTTP/1.1" 404 5176
